Workbook

Sheet README
B2: Security Framework Assessment & Transformation Readiness
B3: Project Tracker Pack — Daily Task Tracker | Prerequisite Checklist | SAP Security SME Questionnaire | Summary Dashboard
B5: How to use this workbook
B6: 1. 'Daily Task Tracker' lays out the build plan day-by-day from kickoff to production handover.
B7: 2. 'Prerequisite Checklist' lists everything to secure (access, approvals, infra) before collectors run on any system.
B8: 3. 'SME Questionnaire' is what to walk through with the SAP Security SME(s) — internal and, later, per customer.
B9: 4. 'Summary Dashboard' auto-rolls up workload and completion status from the other sheets — nothing to fill in there.
B10: 5. Update the Project Start Date below — the Date column on the Daily Task Tracker recalculates automatically (skips weekends).
B11: 6. Status, Priority, and Owner cells use dropdowns (data validation) — click the cell and choose from the list.
B13: Project Start Date (input) | C13: 46216
B15: Team & Assumed Roles
B16: Note: you confirmed Rohan and Shweta. The plan below assumes a 3rd (SAP Security SME) and 4th (Business/Consulting Lead) seat based on the roles in your reference document — rename these in the Owner columns once confirmed; the structure of the plan does not otherwise change.
B18: Owner Label Used In Sheets | C18: Assumed Role | D18: Primary Responsibility in This Plan
B19: Rohan | C19: Project Lead / Developer | D19: Architecture, scoring engine, baseline library, ECS/RISE boundary logic, SME coordination
B20: Shweta | C20: Developer | D20: Collector scripts, AI/report generation layer, testing, environment setup
B21: SAP Security SME | C21: SAP Security Subject Matter Expert | D21: Baseline validation, technical accuracy review, mandatory sign-off before customer delivery
B22: Business/Consulting Lead | C22: Sales / Consulting Lead | D22: Customer coordination, access requests, commercial packaging, pilot logistics
B24: Timeline assumption
B25: ~9 working weeks (43 working days) from kickoff to production handover, with a 2-person build team, 1 SME, and 1 business/consulting lead running in parallel. Adjust pace in the Daily Task Tracker if your team's availability differs (e.g. part-time SME).

Sheet Daily Task Tracker
A1: Day | B1: Date | C1: Week | D1: Phase | E1: Task | F1: Subtask | G1: Owner | H1: Est. Hours | I1: Status | J1: Dependencies | K1: Deliverable | L1: Comments
A2: 1 | B2: =WORKDAY(README!$C$13-1,A2) -> 46216 | C2: 1 | D2: Phase 0 - Discovery & SME Alignment | E2: Project Kickoff & Scope Alignment | F2: Kickoff meeting - align scope, success criteria, timeline, RACI | G2: Rohan | H2: 2 | I2: Not Started | J2: None | K2: Signed-off scope note | L2: All 4 attend
A3: 1 | B3: =WORKDAY(README!$C$13-1,A3) -> 46216 | C3: 1 | D3: Phase 0 - Discovery & SME Alignment | E3: Project Kickoff & Scope Alignment | F3: Review prior SAP security assessment collateral & this reference doc | G3: Rohan | H3: 2 | I3: Not Started | J3: None | K3: Discovery notes v0
A4: 1 | B4: =WORKDAY(README!$C$13-1,A4) -> 46216 | C4: 1 | D4: Phase 0 - Discovery & SME Alignment | E4: Project Kickoff & Scope Alignment | F4: Set up project workspace - shared drive, board (Jira/Trello), Git repo | G4: Shweta | H4: 3 | I4: Not Started | J4: None | K4: Project workspace live
A5: 1 | B5: =WORKDAY(README!$C$13-1,A5) -> 46216 | C5: 1 | D5: Phase 0 - Discovery & SME Alignment | E5: Project Kickoff & Scope Alignment | F5: Draft SME questionnaire distribution list & interview schedule | G5: Business/Consulting Lead | H5: 2 | I5: Not Started | J5: None | K5: Interview schedule | L5: Book SME calendar early
A6: 2 | B6: =WORKDAY(README!$C$13-1,A6) -> 46217 | C6: 1 | D6: Phase 0 - Discovery & SME Alignment | E6: SME Questionnaire Kickoff | F6: Finalize and circulate SME Questionnaire v1 to internal SME | G6: Rohan | H6: 2 | I6: Not Started | J6: Day 1 kickoff | K6: SME Questionnaire sent
A7: 2 | B7: =WORKDAY(README!$C$13-1,A7) -> 46217 | C7: 1 | D7: Phase 0 - Discovery & SME Alignment | E7: SME Questionnaire Kickoff | F7: Research RISE/ECS responsibility matrix (SAP contract docs, OSS notes) | G7: Rohan | H7: 3 | I7: Not Started | J7: None | K7: ECS boundary notes v0 | L7: Critical for scoring model
A8: 2 | B8: =WORKDAY(README!$C$13-1,A8) -> 46217 | C8: 1 | D8: Phase 0 - Discovery & SME Alignment | E8: SME Questionnaire Kickoff | F8: Set up Python dev environment - repo scaffold, linting, CI skeleton | G8: Shweta | H8: 4 | I8: Not Started | J8: Workspace live | K8: Dev environment ready
A9: 2 | B9: =WORKDAY(README!$C$13-1,A9) -> 46217 | C9: 1 | D9: Phase 0 - Discovery & SME Alignment | E9: SME Questionnaire Kickoff | F9: Confirm SME availability windows for interviews (Days 3-5) | G9: Business/Consulting Lead | H9: 1 | I9: Not Started | J9: Interview schedule | K9: Confirmed calendar invites
A10: 3 | B10: =WORKDAY(README!$C$13-1,A10) -> 46218 | C10: 1 | D10: Phase 0 - Discovery & SME Alignment | E10: SME Interview #1 - Auth Concept & Role Design | F10: SME interview - authorization concept, role design standards, naming conventions | G10: Rohan | H10: 2 | I10: Not Started | J10: SME available | K10: Interview notes - Auth Concept | L10: SME co-attends
A11: 3 | B11: =WORKDAY(README!$C$13-1,A11) -> 46218 | C11: 1 | D11: Phase 0 - Discovery & SME Alignment | E11: SME Interview #1 - Auth Concept & Role Design | F11: Research SAP security baseline standards (SAP Security Baseline, DSAG, BSI) | G11: Shweta | H11: 3 | I11: Not Started | J11: None | K11: Baseline research pack
A12: 3 | B12: =WORKDAY(README!$C$13-1,A12) -> 46218 | C12: 1 | D12: Phase 0 - Discovery & SME Alignment | E12: SME Interview #1 - Auth Concept & Role Design | F12: Document RISE/ECS boundary rules per technical domain (params/RFC/gateway) | G12: Rohan | H12: 2 | I12: Not Started | J12: ECS boundary notes v0 | K12: ECS boundary matrix v1 | L12: Key risk item from brief
A13: 3 | B13: =WORKDAY(README!$C$13-1,A13) -> 46218 | C13: 1 | D13: Phase 0 - Discovery & SME Alignment | E13: SME Interview #1 - Auth Concept & Role Design | F13: Draft initial data source inventory (tables/tcodes/reports needed) | G13: Shweta | H13: 2 | I13: Not Started | J13: Baseline research pack | K13: Data source inventory v0 | L13: AGR_*, USR*, TSTC, RSPARAM etc.
A14: 4 | B14: =WORKDAY(README!$C$13-1,A14) -> 46219 | C14: 1 | D14: Phase 0 - Discovery & SME Alignment | E14: SME Interview #2 - RFC, Gateway & Critical Auths | F14: SME interview - RFC destination hardening, gateway ACLs, critical basis auths | G14: Rohan | H14: 2 | I14: Not Started | J14: Day 3 notes | K14: Interview notes - RFC/Gateway
A15: 4 | B15: =WORKDAY(README!$C$13-1,A15) -> 46219 | C15: 1 | D15: Phase 0 - Discovery & SME Alignment | E15: SME Interview #2 - RFC, Gateway & Critical Auths | F15: Define read-only technical user + authorization profile for collectors | G15: Shweta | H15: 3 | I15: Not Started | J15: Data source inventory v0 | K15: Technical user auth spec v0 | L15: Feeds Prerequisite Checklist
A16: 4 | B16: =WORKDAY(README!$C$13-1,A16) -> 46219 | C16: 1 | D16: Phase 0 - Discovery & SME Alignment | E16: SME Interview #2 - RFC, Gateway & Critical Auths | F16: Draft prerequisite access request template for customer Basis team | G16: Business/Consulting Lead | H16: 2 | I16: Not Started | J16: Technical user auth spec v0 | K16: Access request template
A17: 4 | B17: =WORKDAY(README!$C$13-1,A17) -> 46219 | C17: 1 | D17: Phase 0 - Discovery & SME Alignment | E17: SME Interview #2 - RFC, Gateway & Critical Auths | F17: Consolidate Day 1-4 findings into discovery notes | G17: Rohan | H17: 1 | I17: Not Started | J17: All prior interviews | K17: Discovery notes v1
A18: 5 | B18: =WORKDAY(README!$C$13-1,A18) -> 46220 | C18: 1 | D18: Phase 0 - Discovery & SME Alignment | E18: SME Interview #3 - SoD, GRC, Interfaces + Week 1 Close | F18: SME interview - SoD ruleset, GRC maturity, Fiori/OData, transport process | G18: Rohan | H18: 2 | I18: Not Started | J18: Day 4 notes | K18: Interview notes - SoD/GRC/Interfaces
A19: 5 | B19: =WORKDAY(README!$C$13-1,A19) -> 46220 | C19: 1 | D19: Phase 0 - Discovery & SME Alignment | E19: SME Interview #3 - SoD, GRC, Interfaces + Week 1 Close | F19: Finalize Prerequisite Checklist v1 (draft) | G19: Shweta | H19: 3 | I19: Not Started | J19: Technical user auth spec v0 | K19: Prerequisite Checklist v1
A20: 5 | B20: =WORKDAY(README!$C$13-1,A20) -> 46220 | C20: 1 | D20: Phase 0 - Discovery & SME Alignment | E20: SME Interview #3 - SoD, GRC, Interfaces + Week 1 Close | F20: Finalize SME Questionnaire v1 - fold in internal SME feedback | G20: Rohan | H20: 2 | I20: Not Started | J20: SME Questionnaire sent | K20: SME Questionnaire v1 (final)
A21: 5 | B21: =WORKDAY(README!$C$13-1,A21) -> 46220 | C21: 1 | D21: Phase 0 - Discovery & SME Alignment | E21: SME Interview #3 - SoD, GRC, Interfaces + Week 1 Close | F21: Week 1 retro & Week 2 planning | G21: Rohan | H21: 1 | I21: Not Started | J21: None | K21: Week 2 plan | L21: All 4 attend
A22: 6 | B22: =WORKDAY(README!$C$13-1,A22) -> 46223 | C22: 2 | D22: Phase 1 - Baseline Library & Scoring Model Design | E22: Baseline Library Structure | F22: Design baseline library schema (YAML/JSON) - one entry per control | G22: Shweta | H22: 4 | I22: Not Started | J22: Baseline research pack | K22: Baseline schema v0
A23: 6 | B23: =WORKDAY(README!$C$13-1,A23) -> 46223 | C23: 2 | D23: Phase 1 - Baseline Library & Scoring Model Design | E23: Baseline Library Structure | F23: Define control categories: auth concept, params, RFC, gateway, critical auths, interfaces, SoD | G23: Rohan | H23: 3 | I23: Not Started | J23: Baseline schema v0 | K23: Control taxonomy v1
A24: 6 | B24: =WORKDAY(README!$C$13-1,A24) -> 46223 | C24: 2 | D24: Phase 1 - Baseline Library & Scoring Model Design | E24: Baseline Library Structure | F24: Map SAP-recommended baseline values (login/password policy, auth switches, etc.) | G24: Rohan | H24: 3 | I24: Not Started | J24: Control taxonomy v1 | K24: Baseline values v0 | L24: SME to validate Day 7
A25: 6 | B25: =WORKDAY(README!$C$13-1,A25) -> 46223 | C25: 2 | D25: Phase 1 - Baseline Library & Scoring Model Design | E25: Baseline Library Structure | F25: Tag ECS/RISE ownership flag against each baseline entry | G25: Rohan | H25: 2 | I25: Not Started | J25: ECS boundary matrix v1 | K25: Baseline entries flagged | L25: Ties to key risk in brief
A26: 7 | B26: =WORKDAY(README!$C$13-1,A26) -> 46224 | C26: 2 | D26: Phase 1 - Baseline Library & Scoring Model Design | E26: Scoring Model Design | F26: Define maturity model (0-5 levels) per control category | G26: Rohan | H26: 3 | I26: Not Started | J26: Control taxonomy v1 | K26: Maturity model v1
A27: 7 | B27: =WORKDAY(README!$C$13-1,A27) -> 46224 | C27: 2 | D27: Phase 1 - Baseline Library & Scoring Model Design | E27: Scoring Model Design | F27: Define weighting/scoring algorithm (control criticality x compliance gap) | G27: Shweta | H27: 3 | I27: Not Started | J27: Maturity model v1 | K27: Scoring algorithm spec v0
A28: 7 | B28: =WORKDAY(README!$C$13-1,A28) -> 46224 | C28: 2 | D28: Phase 1 - Baseline Library & Scoring Model Design | E28: Scoring Model Design | F28: Design transformation readiness dimensions (auth complexity, custom code, interfaces) | G28: Rohan | H28: 3 | I28: Not Started | J28: Maturity model v1 | K28: Readiness scoring spec v0
A29: 7 | B29: =WORKDAY(README!$C$13-1,A29) -> 46224 | C29: 2 | D29: Phase 1 - Baseline Library & Scoring Model Design | E29: Scoring Model Design | F29: SME review of maturity levels for technical accuracy | G29: SAP Security SME | H29: 2 | I29: Not Started | J29: Maturity model v1 | K29: SME feedback log | L29: Mandatory review gate
A30: 8 | B30: =WORKDAY(README!$C$13-1,A30) -> 46225 | C30: 2 | D30: Phase 1 - Baseline Library & Scoring Model Design | E30: Collector Scope Definition | F30: Finalize RFC-enabled function modules / read APIs needed per data source | G30: Shweta | H30: 3 | I30: Not Started | J30: Data source inventory v0 | K30: Collector API list v1
A31: 8 | B31: =WORKDAY(README!$C$13-1,A31) -> 46225 | C31: 2 | D31: Phase 1 - Baseline Library & Scoring Model Design | E31: Collector Scope Definition | F31: Validate read-only sufficiency of each API with SME (no execute risk) | G31: SAP Security SME | H31: 2 | I31: Not Started | J31: Collector API list v1 | K31: Read-only validation sign-off | L31: Guardrail: read-only only
A32: 8 | B32: =WORKDAY(README!$C$13-1,A32) -> 46225 | C32: 2 | D32: Phase 1 - Baseline Library & Scoring Model Design | E32: Collector Scope Definition | F32: Draft collector script architecture - modular per security domain | G32: Rohan | H32: 3 | I32: Not Started | J32: Collector API list v1 | K32: Collector architecture v1
A33: 8 | B33: =WORKDAY(README!$C$13-1,A33) -> 46225 | C33: 2 | D33: Phase 1 - Baseline Library & Scoring Model Design | E33: Collector Scope Definition | F33: Define collector output JSON schema | G33: Shweta | H33: 2 | I33: Not Started | J33: Collector architecture v1 | K33: Collector output schema v1
A34: 9 | B34: =WORKDAY(README!$C$13-1,A34) -> 46226 | C34: 2 | D34: Phase 1 - Baseline Library & Scoring Model Design | E34: Reporting & Roadmap Design | F34: Design LLM prompt templates for findings narrative generation | G34: Rohan | H34: 3 | I34: Not Started | J34: Scoring algorithm spec v0 | K34: Prompt templates v0
A35: 9 | B35: =WORKDAY(README!$C$13-1,A35) -> 46226 | C35: 2 | D35: Phase 1 - Baseline Library & Scoring Model Design | E35: Reporting & Roadmap Design | F35: Define report structure - exec summary, technical findings, gap analysis, roadmap | G35: Rohan | H35: 2 | I35: Not Started | J35: Prompt templates v0 | K35: Report structure spec v1
A36: 9 | B36: =WORKDAY(README!$C$13-1,A36) -> 46226 | C36: 2 | D36: Phase 1 - Baseline Library & Scoring Model Design | E36: Reporting & Roadmap Design | F36: Draft remediation prioritization logic (risk x effort matrix) | G36: Shweta | H36: 3 | I36: Not Started | J36: Readiness scoring spec v0 | K36: Prioritization logic v0
A37: 9 | B37: =WORKDAY(README!$C$13-1,A37) -> 46226 | C37: 2 | D37: Phase 1 - Baseline Library & Scoring Model Design | E37: Reporting & Roadmap Design | F37: Draft customer-facing roadmap deck template outline | G37: Business/Consulting Lead | H37: 2 | I37: Not Started | J37: Report structure spec v1 | K37: Deck outline v0
A38: 10 | B38: =WORKDAY(README!$C$13-1,A38) -> 46227 | C38: 2 | D38: Phase 1 - Baseline Library & Scoring Model Design | E38: Design Review & Sign-off (Week 2 Close) | F38: Internal design review - architecture, scoring model, baseline library | G38: Rohan | H38: 2 | I38: Not Started | J38: All Week 2 outputs | K38: Design review notes | L38: All 4 attend
A39: 10 | B39: =WORKDAY(README!$C$13-1,A39) -> 46227 | C39: 2 | D39: Phase 1 - Baseline Library & Scoring Model Design | E39: Design Review & Sign-off (Week 2 Close) | F39: SME sign-off on Baseline Library v1 | G39: SAP Security SME | H39: 2 | I39: Not Started | J39: Baseline entries flagged | K39: Baseline Library v1 (signed off) | L39: Version-controlled per guardrail
A40: 10 | B40: =WORKDAY(README!$C$13-1,A40) -> 46227 | C40: 2 | D40: Phase 1 - Baseline Library & Scoring Model Design | E40: Design Review & Sign-off (Week 2 Close) | F40: Finalize Prerequisite Checklist v2 with access/API findings | G40: Shweta | H40: 2 | I40: Not Started | J40: Collector API list v1 | K40: Prerequisite Checklist v2
...

Sheet Prerequisite Checklist
A1: # | B1: Category | C1: Checklist Item | D1: Description / Requirement | E1: Required From | F1: Priority | G1: Status | H1: Owner | I1: Notes
A2: 1 | B2: SAP System Access | C2: Test/sandbox SAP system available (ECC or S/4) | D2: Non-production system for internal dev and collector testing, not an empty client | E2: Internal IT/Basis | F2: High | G2: Not Started | H2: Rohan
A3: 2 | B3: SAP System Access | C3: Representative test system with real-ish data | D3: Populated roles, RFCs, parameters - not a vanilla client - so collectors have something meaningful to read | E3: Internal IT/Basis | F3: High | G3: Not Started | H3: Rohan
A4: 3 | B4: SAP System Access | C4: Dedicated technical/communication user created | D4: Read-only, S_RFC-based communication user for collector to log on as | E4: Internal Basis Team | F4: High | G4: Not Started | H4: Shweta
A5: 4 | B5: SAP System Access | C5: Remote connectivity to test system configured | D5: VPN/SAProuter access from collector host to the SAP application server | E5: Internal IT | F5: Medium | G5: Not Started | H5: Shweta
A6: 5 | B6: Authorizations | C6: Least-privilege auth profile for technical user | D6: Display-only auth objects: S_TABU_DIS (display), S_RFC, S_USER_GRP (display), S_TCODE for SUIM/SM59/RZ11 (display) | E6: Internal Basis/SME | F6: High | G6: Not Started | H6: SAP Security SME
A7: 6 | B7: Authorizations | C7: Confirm no write/execute rights on collector user | D7: No S_TABU_DIS write, no RFC test-connection execute, no BAPI execute beyond the approved read list | E7: SAP Security SME | F7: High | G7: Not Started | H7: SAP Security SME
A8: 7 | B8: Authorizations | C8: Written least-privilege confirmation on file | D8: Signed note from SME/Basis confirming the technical user's authorization scope before first run | E8: SAP Security SME | F8: High | G8: Not Started | H8: SAP Security SME
A9: 8 | B9: Data Sources | C9: Finalized table read list confirmed accessible | D9: AGR_*, USR*, UST*, TSTC, TSTCT, TOBJ, USOBT_C, USOBX_C - confirm technical user can read each | E9: SAP Security SME | F9: High | G9: Not Started | H9: Shweta
A10: 9 | B10: Data Sources | C10: Finalized transaction/report list confirmed accessible | D10: SUIM, RZ10, RZ11, SM59, SICF, SM20/RSAU - confirm display access | E10: SAP Security SME | F10: High | G10: Not Started | H10: Shweta
A11: 10 | B11: Data Sources | C11: Table read method decided (RFC_READ_TABLE vs custom Z-RFC) | D11: Decide and document; if a custom Z-RFC is required, treat as a build dependency | E11: Rohan / SAP Security SME | F11: High | G11: Not Started | H11: Rohan
A12: 11 | B12: Data Sources | C12: Transport request raised for any custom Z-RFC | D12: If a Z-RFC module is required for read access, get it built, tested, and transported | E12: Basis/Transport Team | F12: Medium | G12: Not Started | H12: Shweta
A13: 12 | B13: RFC / Gateway | C13: List of RFC destinations to inspect confirmed (SM59) | D13: Scope which RFC destinations are in-bounds for the assessment | E13: SAP Security SME | F13: Medium | G13: Not Started | H13: Rohan
... A29: 28 | B29: Documentation / Baseline | C29: SME sign-off document on baseline thresholds | D29: Written confirmation the maturity thresholds are technically sound | E29: SAP Security SME | F29: High | G29: Not Started | H29: SAP Security SME

Sheet SME Questionnaire
A1: # | B1: Section | C1: Question | D1: Purpose | E1: Priority | F1: Mandatory/Optional | G1: Responsible Person (Customer-side) | H1: Answer / Notes
A2: 1 | B2: Current Landscape | C2: How many SAP systems (Dev/QA/Prod) and clients are in scope for this assessment? | D2: Defines collector deployment scope and effort estimate | E2: High | F2: Mandatory | G2: Basis Lead
A3: 2 | B3: Current Landscape | C3: What SAP product versions are in use (ECC EhP level, S/4HANA version)? | D3: Determines which baseline entries and collectors apply | E3: High | F3: Mandatory | G3: Basis Lead
A4: 3 | B4: Current Landscape | C4: Is the customer on SAP RISE/ECS? If so, which service tier? | D4: Directly determines the ECS/RISE scoring boundary - critical guardrail | E4: High | F4: Mandatory | G4: Basis Lead / Contract Owner
A5: 4 | B5: Current Landscape | C5: What is the target S/4 transformation approach (Brownfield/Greenfield/Bluefield) and timeline? | D5: Frames the transformation-readiness scoring context | E5: High | F5: Mandatory | G5: Project Sponsor
A6: 5 | B6: Authorization Concept | C6: Is the authorization concept role-based (single/composite/derived roles) or legacy activity-group based? | D6: Baseline for role quality scoring | E6: High | F6: Mandatory | G6: Security Lead
A7: 6 | B7: Authorization Concept | C7: What naming convention is used for roles, and is it consistently applied? | D7: Feeds role hygiene sub-score | E7: Medium | F7: Optional | G7: Security Lead
A8: 7 | B8: Authorization Concept | C8: Are there SAP_ALL / SAP_NEW assignments in production? To whom, and why? | D8: Critical-authorization risk input | E8: High | F8: Mandatory | G8: Security Lead
A9: 8 | B9: Authorization Concept | C9: How frequently are role authorizations reviewed or recertified, and by whom? | D9: Maturity-model input on governance | E9: Medium | F9: Mandatory | G9: Security Lead
A10: 9 | B10: Profiles & Parameters | C10: Are RSPARAM/profile parameters centrally managed (RZ10) with change control? | D10: Governance maturity input | E10: Medium | F10: Mandatory | G10: Basis Lead
A11: 10 | B11: Profiles & Parameters | C11: Are there known deviations from SAP-recommended security parameters today? | D11: Pre-identifies likely gaps before the collector run | E11: Medium | F11: Optional | G11: Basis Lead
A12: 11 | B12: User Management | C12: How are standard users (SAP*, DDIC, EARLYWATCH, TMSADM) managed - locked, passwords changed, monitored? | D12: Standard-user risk scoring | E12: High | F12: Mandatory | G12: Security Lead
A13: 12 | B13: User Management | C13: What is the joiner-mover-leaver process for SAP user provisioning/deprovisioning? | D13: Maturity-model input on user lifecycle | E13: Medium | F13: Mandatory | G13: Security Lead
... A34: 33 | B34: Future Roadmap | C34: Are there plans to adopt SAP GRC, expand Fiori, or move toward Zero Trust network access post go-live? | D34: Ensures the roadmap aligns with where the landscape is heading, not just where it is today | E34: Low | F34: Optional | G34: Project Sponsor

Sheet Summary Dashboard
B2: Summary Dashboard
B3: Auto-calculated from the other sheets. Nothing to fill in here - just update Status/Owner cells on the other tabs.
B5: Workload by Owner - Daily Task Tracker
B6: Owner | C6: Subtasks Assigned | D6: Total Est. Hours | E6: Completed | F6: % Complete
B7: Rohan | C7: =COUNTIF('Daily Task Tracker'!$G$2:$G$112,B7) -> 49 | D7: =SUMIF('Daily Task Tracker'!$G$2:$G$112,B7,'Daily Task Tracker'!$H$2:$H$112) -> 136 | E7: =COUNTIFS('Daily Task Tracker'!$G$2:$G$112,B7,'Daily Task Tracker'!$I$2:$I$112,"Complete") -> 0 | F7: =IF(C7=0,0,E7/C7) -> 0
B8: Shweta | C8: =COUNTIF('Daily Task Tracker'!$G$2:$G$112,B8) -> 40 | D8: =SUMIF('Daily Task Tracker'!$G$2:$G$112,B8,'Daily Task Tracker'!$H$2:$H$112) -> 141 | E8: =COUNTIFS('Daily Task Tracker'!$G$2:$G$112,B8,'Daily Task Tracker'!$I$2:$I$112,"Complete") -> 0 | F8: =IF(C8=0,0,E8/C8) -> 0
B9: SAP Security SME | C9: =COUNTIF('Daily Task Tracker'!$G$2:$G$112,B9) -> 11 | D9: =SUMIF('Daily Task Tracker'!$G$2:$G$112,B9,'Daily Task Tracker'!$H$2:$H$112) -> 27 | E9: =COUNTIFS('Daily Task Tracker'!$G$2:$G$112,B9,'Daily Task Tracker'!$I$2:$I$112,"Complete") -> 0 | F9: =IF(C9=0,0,E9/C9) -> 0
B10: Business/Consulting Lead | C10: =COUNTIF('Daily Task Tracker'!$G$2:$G$112,B10) -> 11 | D10: =SUMIF('Daily Task Tracker'!$G$2:$G$112,B10,'Daily Task Tracker'!$H$2:$H$112) -> 30 | E10: =COUNTIFS('Daily Task Tracker'!$G$2:$G$112,B10,'Daily Task Tracker'!$I$2:$I$112,"Complete") -> 0 | F10: =IF(C10=0,0,E10/C10) -> 0
B12: Total | C12: =SUM(C7:C10) -> 111 | D12: =SUM(D7:D10) -> 334 | E12: =SUM(E7:E10) -> 0
B15: Progress by Phase - Daily Task Tracker
B16: Phase | C16: Subtasks | D16: Total Est. Hours | E16: Completed | F16: % Complete
B17: Phase 0 - Discovery & SME Alignment | C17: =COUNTIF('Daily Task Tracker'!$D$2:$D$112,B17) -> 20 | D17: =SUMIF('Daily Task Tracker'!$D$2:$D$112,B17,'Daily Task Tracker'!$H$2:$H$112) -> 44 | E17: =COUNTIFS('Daily Task Tracker'!$D$2:$D$112,B17,'Daily Task Tracker'!$I$2:$I$112,"Complete") -> 0 | F17: =IF(C17=0,0,E17/C17) -> 0
B18: Phase 1 - Baseline Library & Scoring Model Design | C18: =COUNTIF('Daily Task Tracker'!$D$2:$D$112,B18) -> 20 | D18: =SUMIF('Daily Task Tracker'!$D$2:$D$112,B18,'Daily Task Tracker'!$H$2:$H$112) -> 50 | E18: =COUNTIFS('Daily Task Tracker'!$D$2:$D$112,B18,'Daily Task Tracker'!$I$2:$I$112,"Complete") -> 0 | F18: =IF(C18=0,0,E18/C18) -> 0
B19: Phase 2 - Collector Script Development | C19: =COUNTIF('Daily Task Tracker'!$D$2:$D$112,B19) -> 22 | D19: =SUMIF('Daily Task Tracker'!$D$2:$D$112,B19,'Daily Task Tracker'!$H$2:$H$112) -> 77 | E19: =COUNTIFS('Daily Task Tracker'!$D$2:$D$112,B19,'Daily Task Tracker'!$I$2:$I$112,"Complete") -> 0 | F19: =IF(C19=0,0,E19/C19) -> 0
B20: Phase 3 - Scoring Engine Development | C20: =COUNTIF('Daily Task Tracker'!$D$2:$D$112,B20) -> 11 | D20: =SUMIF('Daily Task Tracker'!$D$2:$D$112,B20,'Daily Task Tracker'!$H$2:$H$112) -> 40 | E20: =COUNTIFS('Daily Task Tracker'!$D$2:$D$112,B20,'Daily Task Tracker'!$I$2:$I$112,"Complete") -> 0 | F20: =IF(C20=0,0,E20/C20) -> 0
B21: Phase 4 - AI Reporting & Roadmap Layer | C21: =COUNTIF('Daily Task Tracker'!$D$2:$D$112,B21) -> 11 | D21: =SUMIF('Daily Task Tracker'!$D$2:$D$112,B21,'Daily Task Tracker'!$H$2:$H$112) -> 38 | E21: =COUNTIFS('Daily Task Tracker'!$D$2:$D$112,B21,'Daily Task Tracker'!$I$2:$I$112,"Complete") -> 0 | F21: =IF(C21=0,0,E21/C21) -> 0
B22: Phase 5 - Testing (Unit/Integration/Security) | C22: =COUNTIF('Daily Task Tracker'!$D$2:$D$112,B22) -> 10 | D22: =SUMIF('Daily Task Tracker'!$D$2:$D$112,B22,'Daily Task Tracker'!$H$2:$H$112) -> 34 | E22: =COUNTIFS('Daily Task Tracker'!$D$2:$D$112,B22,'Daily Task Tracker'!$I$2:$I$112,"Complete") -> 0 | F22: =IF(C22=0,0,E22/C22) -> 0
B23: Phase 6 - Pilot Run & Refinement | C23: =COUNTIF('Daily Task Tracker'!$D$2:$D$112,B23) -> 11 | D23: =SUMIF('Daily Task Tracker'!$D$2:$D$112,B23,'Daily Task Tracker'!$H$2:$H$112) -> 32 | E23: =COUNTIFS('Daily Task Tracker'!$D$2:$D$112,B23,'Daily Task Tracker'!$I$2:$I$112,"Complete") -> 0 | F23: =IF(C23=0,0,E23/C23) -> 0
B24: Phase 7 - Productionization & Handover | C24: =COUNTIF('Daily Task Tracker'!$D$2:$D$112,B24) -> 6 | D24: =SUMIF('Daily Task Tracker'!$D$2:$D$112,B24,'Daily Task Tracker'!$H$2:$H$112) -> 19 | E24: =COUNTIFS('Daily Task Tracker'!$D$2:$D$112,B24,'Daily Task Tracker'!$I$2:$I$112,"Complete") -> 0 | F24: =IF(C24=0,0,E24/C24) -> 0
B27: Overall Completion by Sheet
B28: Sheet | C28: Total Items | D28: Complete | E28: % Complete
B29: Daily Task Tracker (subtasks) | C29: =COUNTA('Daily Task Tracker'!$A$2:$A$112) -> 111 | D29: =COUNTIF('Daily Task Tracker'!$I$2:$I$112,"Complete") -> 0 | E29: =IF(C29=0,0,D29/C29) -> 0
B30: Prerequisite Checklist | C30: =COUNTA('Prerequisite Checklist'!$A$2:$A$29) -> 28 | D30: =COUNTIF('Prerequisite Checklist'!$G$2:$G$29,"Complete") -> 0 | E30: =IF(C30=0,0,D30/C30) -> 0
B31: SME Questionnaire (answered = Answer/Notes filled) | C31: =COUNTA('SME Questionnaire'!$A$2:$A$34) -> 33 | D31: =COUNTIF('SME Questionnaire'!$H$2:$H$34,"?*") -> 0 | E31: =IF(C31=0,0,D31/C31) -> 0
